<?xml version="1.0" ?>
<robot name="ADARS">
  <link name="base_link">
    <visual>
      <geometry>
        <mesh filename="BMM3/estructura_asm.dae"/>
      </geometry>
    </visual>
    <collision>
      <origin xyz="0 0 0.375"/>
      <geometry>
        <cylinder radius="0.4" length="0.75"/>
      </geometry>
      <material name="grey">
        <color rgba="0.8 0.83 0.94 1"/>
      </material>
    </collision>
    <collision>
      <origin xyz="0 0 1.395"/>
      <geometry>
        <box size="0.45 0.08 0.05"/>
      </geometry>
      <material name="grey"/>
    </collision>
    <collision>
      <origin xyz="0 0 1.056"/>
      <geometry>
        <box size="0.08 0.08 0.63"/>
      </geometry>
      <material name="grey"/>
    </collision>
    <collision>
      <origin xyz="0 -0.09 0.916"/>
      <geometry>
        <box size="0.43 0.1 0.33"/>
      </geometry>
      <material name="grey"/>
    </collision>
  </link>
  
  <joint name="motor_1" type="revolute">
    <parent link="base_link"/>
    <child link="wheel_1"/>
    <origin rpy="2.0944 0 1.5708" xyz="0 -0.2905 0.1"/>
    <axis xyz="-1 0 0"/>
    <limit lower="-6.2831853" upper="6.2831853"/>
  </joint>
 
  <link name="wheel_1">
    <visual>
      <geometry>
        <mesh filename="BMM3/wheel.dae"/>
      </geometry>
    </visual>
    <collision>
      <geometry>
        <sphere radius="0.10"/>
      </geometry>
      <material name="black"/>
    </collision>
  </link>
  
  <joint name="motor_2" type="revolute">
    <parent link="base_link"/>
    <child link="wheel_2"/>
    <origin rpy="0 0 3.66519" xyz="0.25158 0.14525 0.1"/>
    <axis xyz="-1 0 0"/>
    <limit lower="-6.2831853" upper="6.2831853"/>
  </joint>
 
  <link name="wheel_2">
    <visual>
      <geometry>
        <mesh filename="BMM3/wheel.dae"/>
      </geometry>
    </visual>
    <collision>
      <geometry>
        <sphere radius="0.10"/>
      </geometry>
      <material name="black"/>
    </collision>
  </link>
  
  <joint name="motor_3" type="revolute">
    <parent link="base_link"/>
    <child link="wheel_3"/>
    <origin rpy="0 0 5.75959" xyz="-0.25158 0.14525 0.1"/>
    <axis xyz="-1 0 0"/>
    <limit lower="-6.2831853" upper="6.2831853"/>
  </joint>
 
  <link name="wheel_3">
    <visual>
      <geometry>
        <mesh filename="BMM3/wheel.dae"/>
      </geometry>
    </visual>
    <collision>
      <geometry>
        <sphere radius="0.10"/>
      </geometry>
      <material name="black"/>
    </collision>
  </link>
</robot>

