<robot name="BMM3">

  <link name="base_link">
    <visual>
      <geometry>
        <mesh filename="package://bmm3/models/BMM3/BMM3_DAE/estructura_asm.dae"/>
      </geometry>
    </visual>
    <collision>
      <origin xyz="0 0 0.375"/>
      <geometry>
        <cylinder radius="0.4" length="0.75"/>
      </geometry>
      <material name="grey">
        <color rgba="0.8 0.83 0.94 1"/>
      </material>
      </collision>
      <collision>
        <origin xyz="0 0 1.395"/>
        <geometry>
          <box size="0.45 0.08 0.05"/>
        </geometry>
        <material name="grey"/>
      </collision>
      <collision>
        <origin xyz="0 0 1.056"/>
        <geometry>
          <box size="0.08 0.08 0.63"/>
        </geometry>
        <material name="grey"/>
      </collision>
      <collision>
        <origin xyz="0 -0.09 0.916"/>
        <geometry>
          <box size="0.43 0.1 0.33"/>
        </geometry>
        <material name="grey"/>
      </collision>
  </link>

  <joint name="motor_1" type="revolute">
    <parent link="base_link"/>
    <child link="wheel_1"/>
    <origin rpy="2.0944 0 1.5708" xyz="0 -0.2905 0.1"/>
    <axis xyz="-1 0 0"/>
    <limit effort="150.0" lower="-6.2831853" upper="6.2831853" velocity="3.15"/>
  </joint>

  <link name="wheel_1">
    <parent link="base_link"/> 
    <visual>
      <geometry>
        <mesh filename="package://bmm3/models/BMM3/BMM3_DAE/wheel.dae"/>
      </geometry>
    </visual>
    <collision>
      <geometry>
        <sphere radius="0.10"/>
      </geometry>
      <material name="black"/>
    </collision>
  </link>

  <joint name="motor_2" type="revolute">
    <parent link="base_link"/>
    <child link="wheel_2"/>
    <origin rpy="0 0 3.66519" xyz="0.25158 0.14525 0.1"/>
    <axis xyz="-1 0 0"/>
    <limit effort="150.0" lower="-6.2831853" upper="6.2831853" velocity="3.15"/>
  </joint>
 
  <link name="wheel_2">
    <visual>
      <geometry>
        <mesh filename="package://bmm3/models/BMM3/BMM3_DAE/wheel.dae"/>
      </geometry>
    </visual>
    <collision>
      <geometry>
        <sphere radius="0.10"/>
      </geometry>
      <material name="black"/>
    </collision>
  </link>

  <joint name="motor_3" type="revolute">
    <parent link="base_link"/>
    <child link="wheel_3"/>
    <origin rpy="0 0 5.75959" xyz="-0.25158 0.14525 0.1"/>
    <axis xyz="-1 0 0"/>
    <limit effort="150.0" lower="-6.2831853" upper="6.2831853" velocity="3.15"/>
  </joint>
 
  <link name="wheel_3">
    <visual>
      <geometry>
        <mesh filename="package://bmm3/models/BMM3/BMM3_DAE/wheel.dae"/>
      </geometry>
    </visual>
    <collision>
      <geometry>
        <sphere radius="0.10"/>
      </geometry>
      <material name="black"/>
    </collision>
  </link>

  <!-- LEFT ARM -->
  <joint name="connector_left" type="fixed">
    <parent link="base_link"/>
    <child link="Base_left"/>
    <origin rpy="0 -2.35619 0" xyz="-0.23963 0.0 1.3890"/>
    <axis xyz="-1 0 0"/>
  </joint>

  <link name="Base_left">
    <visual>
      <geometry>
        <mesh filename="package://bmm3/models/UR5/UR5_DAE/visual/Base.dae"/>
      </geometry>
      <material name="LightGrey">
        <color rgba="0.7 0.7 0.7 1.0"/>
      </material>
    </visual>
    <collision>
      <origin rpy="0 0 0" xyz="0 0 0"/>
      <geometry>
        <mesh filename="package://bmm3/models/UR5/UR5_DAE/collision/Base.stl"/>
      </geometry>
    </collision> 
    <inertial>
      <mass value="4.0"/>
      <origin rpy="0 0 0" xyz="0.0 0.0 0.0"/>
      <inertia ixx="0.00443333156" ixy="0.0" ixz="0.0" iyy="0.00443333156" iyz="0.0" izz="0.0072"/>
    </inertial>
  </link>

  <joint name="ShoulderPanJoint_left" type="revolute">
    <parent link="Base_left"/>
    <child link="Shoulder_left"/>
    <origin rpy="0.0 0.0 -2.01" xyz="0.0 0.0 0.089159"/>
    <axis xyz="0 0 1"/>
    <limit effort="150.0" lower="-6.2831853" upper="6.2831853" velocity="3.15"/>
    <dynamics damping="0.0" friction="0.0"/>
  </joint>
  
  <link name="Shoulder_left">
    <visual>
      <geometry>
        <mesh filename="package://bmm3/models/UR5/UR5_DAE/visual/Shoulder.dae"/>
      </geometry>
      <material name="LightGrey">
        <color rgba="0.7 0.7 0.7 1.0"/>
      </material>
    </visual>
    <collision>
      <origin rpy="0 0 0"/>
      <geometry>
        <mesh filename="package://bmm3/models/UR5/UR5_DAE/collision/Shoulder.stl"/>
      </geometry>
    </collision>
    <inertial>
      <mass value="3.7"/>
      <origin rpy="0 0 0" xyz="0 0 0"/>
      <inertia ixx="0.010267495893" ixy="0.0" ixz="0.0" iyy="0.010267495893" iyz="0.0" izz="0.00666"/>
    </inertial>
  </link>

  <joint name="ShoulderLiftJoint_left" type="revolute">
    <parent link="Shoulder_left"/>
    <child link="UpperArm_left"/>
    <origin rpy="0.0 0.40 0.0" xyz="0.0 0.13585 0.0"/>
    <axis xyz="0 1 0"/>
    <limit effort="150.0" lower="-6.2831853" upper="6.2831853" velocity="3.15"/>
    <dynamics damping="0.0" friction="0.0"/>
  </joint>
  
  <link name="UpperArm_left">
    <visual>
      <geometry>
        <mesh filename="package://bmm3/models/UR5/UR5_DAE/visual/UpperArm.dae"/>
      </geometry>
      <material name="LightGrey">
        <color rgba="0.7 0.7 0.7 1.0"/>
      </material>
    </visual>
    <collision>
      <origin rpy="0 0 0"/>
      <geometry>
        <mesh filename="package://bmm3/models/UR5/UR5_DAE/collision/UpperArm.stl"/>
      </geometry>
    </collision>
    <inertial>
      <mass value="8.393"/>
      <origin rpy="0 0 0" xyz="0.0 0.0 0.28"/>
      <inertia ixx="0.22689067591" ixy="0.0" ixz="0.0" iyy="0.22689067591" iyz="0.0" izz="0.0151074"/>
    </inertial>
  </link>

  <joint name="ElbowJoint_left" type="revolute">
    <parent link="UpperArm_left"/>
    <child link="ForeArm_left"/>
    <origin rpy="0.0 -1.0 0.0" xyz="0.0 -0.1197 0.425"/>
    <axis xyz="0 1 0"/>
    <limit effort="150.0" lower="-6.2831853" upper="6.2831853" velocity="3.15"/>
    <dynamics damping="0.0" friction="0.0"/>
  </joint>
  
  <link name="ForeArm_left">
    <visual>
      <geometry>
        <mesh filename="package://bmm3/models/UR5/UR5_DAE/visual/Forearm.dae"/>
      </geometry>
      <material name="LightGrey">
        <color rgba="0.7 0.7 0.7 1.0"/>
      </material>
    </visual>
    <collision>
      <origin rpy="0 0 0"/>
      <geometry>
        <mesh filename="package://bmm3/models/UR5/UR5_DAE/collision/ForeArm.stl"/>
      </geometry>
    </collision>
    <inertial>
      <mass value="2.275"/>
      <origin rpy="0 0 0" xyz="0.0 0.0 0.25"/>
      <inertia ixx="0.049443313556" ixy="0.0" ixz="0.0" iyy="0.049443313556" iyz="0.0" izz="0.004095"/>
    </inertial>
  </link>
  
  <joint name="Wrist1Joint_left" type="revolute">
    <parent link="ForeArm_left"/>
    <child link="Wrist1_left"/>
    <origin rpy="0.0 -2.0 0.0" xyz="0.0 0.0 0.39225"/>
    <axis xyz="0 1 0"/>
    <limit effort="28.0" lower="-6.2831853" upper="6.2831853" velocity="3.2"/>
    <dynamics damping="0.0" friction="0.0"/>
  </joint>
  
  <link name="Wrist1_left">
    <visual>
      <geometry>
        <mesh filename="package://bmm3/models/UR5/UR5_DAE/visual/Wrist1.dae"/>
      </geometry>
      <material name="LightGrey">
        <color rgba="0.7 0.7 0.7 1.0"/>
      </material>
    </visual>
    <collision>
      <origin rpy="0 0 0"/>
      <geometry>
        <mesh filename="package://bmm3/models/UR5/UR5_DAE/collision/Wrist1.stl"/>
      </geometry>
    </collision>
    <inertial>
      <mass value="1.219"/>
      <origin rpy="0 0 0" xyz="0.0 0.0 0.0"/>
      <inertia ixx="0.111172755531" ixy="0.0" ixz="0.0" iyy="0.111172755531" iyz="0.0" izz="0.21942"/>
    </inertial>
  </link>
  
  <joint name="Wrist2Joint_left" type="revolute">
    <parent link="Wrist1_left"/>
    <child link="Wrist2_left"/>
    <origin rpy="0.0 0.0 -0.70" xyz="0.0 0.093 0.0"/>
    <axis xyz="0 0 1"/>
    <limit effort="28.0" lower="-6.2831853" upper="6.2831853" velocity="3.2"/>
    <dynamics damping="0.0" friction="0.0"/>
  </joint>
  
  <link name="Wrist2_left">
    <visual>
      <geometry>
        <mesh filename="package://bmm3/models/UR5/UR5_DAE/visual/Wrist2.dae"/>
      </geometry>
      <material name="LightGrey">
        <color rgba="0.7 0.7 0.7 1.0"/>
      </material>
    </visual>
    <collision>
      <origin rpy="0 0 0"/>
      <geometry>
        <mesh filename="package://bmm3/models/UR5/UR5_DAE/collision/Wrist2.stl"/>
      </geometry>
    </collision>
    <inertial>
      <mass value="1.219"/>
      <origin rpy="0 0 0" xyz="0.0 0.0 0.0"/>
      <inertia ixx="0.111172755531" ixy="0.0" ixz="0.0" iyy="0.111172755531" iyz="0.0" izz="0.21942"/>
    </inertial>
  </link>
  
  <joint name="Wrist3Joint_left" type="revolute">
    <parent link="Wrist2_left"/>
    <child link="Wrist3_left"/>
    <origin rpy="0.0 0.0 0.0" xyz="0.0 0.0 0.09465"/>
    <axis xyz="0 1 0"/>
    <limit effort="28.0" lower="-6.2831853" upper="6.2831853" velocity="3.2"/>
    <dynamics damping="0.0" friction="0.0"/>
  </joint>
  
  <link name="Wrist3_left">
    <visual>
      <geometry>
        <mesh filename="package://bmm3/models/UR5/UR5_DAE/visual/Wrist3.dae"/>
      </geometry>
      <material name="LightGrey">
        <color rgba="0.7 0.7 0.7 1.0"/>
      </material>
    </visual>
    <collision>
      <origin rpy="0 0 0"/>
      <geometry>
        <mesh filename="package://bmm3/models/UR5/UR5_DAE/collision/Wrist3.stl"/>
      </geometry>
    </collision>
    <inertial>
      <mass value="0.1879"/>
      <origin rpy="0 0 0" xyz="0.0 0.0 0.0"/>
      <inertia ixx="0.0171364731454" ixy="0.0" ixz="0.0" iyy="0.0171364731454" iyz="0.0" izz="0.033822"/>
    </inertial>
  </link>

  <!-- LEFT HAND -->
  <joint name="SupportJoint_left" type="fixed">
    <parent link="Wrist3_left"/>
    <child link="Support_left"/>
    <origin rpy="-1.570796325 0 0" xyz="0 0.1089 0"/>
  </joint>

  <link name="Support_left">
    <visual>
      <geometry>
        <mesh filename="package://bmm3/models/BMM3/BMM3_DAE/AH_support.dae" scale="0.001 0.001 0.001"/>
      </geometry>
    </visual>
    <collision>
      <material name="grey"/>
      <origin xyz="0 0 -0.0055" rpy="0 0 1.570796327"/>
      <geometry>
         <cylinder radius="0.0355" length="0.043"/>
      </geometry>
    </collision>
  </link>

  <joint name="PalmJoint_left" type="fixed">
    <parent link="Support_left"/>
    <child link="Palm_left"/>
    <origin rpy="0 0 1.570796327" xyz="0 0.009 0.111"/>
  </joint>

  <link name="Palm_left">
    <visual>
      <geometry>
	<mesh filename="package://bmm3/models/BMM3/BMM3_DAE/base_link_left.dae" scale="0.001 0.001 0.001"/>
      </geometry>
    </visual>
    <collision>
      <material name="black"/>
	<origin xyz="-0.009300 0 -0.0475"/>
	<geometry>
	  <box size="0.0408 0.1130 0.095"/>
	</geometry>
    </collision>
  </link>

  <joint name="joint_8.0_left" type="revolute">
      <axis xyz="0 0 1"/>
      <limit effort="1" lower="-0.47" upper="0.47" velocity="1"/>
      <parent link="Palm_left"/>
      <child link="Ring_base_left"/>
      <origin rpy="-0.08726646255 0 0" xyz="0 0.0435 -0.001542"/>
  </joint>

  <link name="Ring_base_left">
    <visual>
      <geometry>
        <mesh filename="package://bmm3/models/BMM3/BMM3_DAE/link_0_0.dae" scale="0.001 0.001 0.001"/>
      </geometry>
      <origin xyz="0 0 0.0164"/>
    </visual>
    <collision>
      <material name="black"/>
      <geometry>
        <box size="0.0196 0.0275 0.0164"/>
      </geometry>
      <origin xyz="0 0 0.0082"/>
    </collision>
  </link>

  <link name="Ring_proximal_left">
    <visual>
      <geometry>
        <mesh filename="package://bmm3/models/BMM3/BMM3_DAE/link_1_0.dae" scale="0.001 0.001 0.001"/>
      </geometry>
      <origin rpy="1.5707963 -1.5707963 0"/>
    </visual>
    <collision>
      <material name="black"/>
      <geometry>
        <box size="0.0196 0.0275 0.054"/>
      </geometry>
      <origin xyz="0 0 0.027"/>
    </collision>
  </link>

  <joint name="joint_9.0_left" type="revolute">
      <limit effort="1" lower="-0.196" upper="1.61" velocity="1"/>
      <axis xyz="0 1 0"/>
      <parent link="Ring_base_left"/>
      <child link="Ring_proximal_left"/>
      <origin xyz="0 0 0.0164"/>
  </joint>

  <link name="Ring_distal_left">
    <visual>
      <geometry>
        <mesh filename="package://bmm3/models/BMM3/BMM3_DAE/link_2_0.dae" scale="0.001 0.001 0.001"/>
      </geometry>
      <origin rpy="-1.5707963 -1.5707963 0"/>
    </visual>
    <collision>
      <material name="black"/>
      <geometry>
        <box size="0.0196 0.0275 0.0384"/>
      </geometry>
      <origin xyz="0 0 0.0192"/>
    </collision>
  </link>
  
  <joint name="joint_10.0_left" type="revolute">
      <axis xyz="0 1 0"/>
      <limit effort="1" lower="-0.174" upper="1.709" velocity="1"/>
      <parent link="Ring_proximal_left"/>
      <child link="Ring_distal_left"/>
      <origin xyz="0 0 0.054"/>
  </joint>

  <link name="Ring_last_left">
    <visual>
      <geometry>
        <mesh filename="package://bmm3/models/BMM3/BMM3_DAE/link_3_0.dae" scale="0.001 0.001 0.001"/>
      </geometry>
      <origin rpy="-1.5707963 -1.5707963 0"/>
    </visual>
    <collision>
      <material name="black"/>
      <geometry>
        <box size="0.0196 0.0275 0.0267"/>
      </geometry>
      <origin xyz="0 0 0.01335"/>
    </collision>
  </link>
  
  <joint name="joint_11.0_left" type="revolute">
      <axis xyz="0 1 0"/>
      <limit effort="1" lower="-0.227" upper="1.618" velocity="1"/>
      <parent link="Ring_distal_left"/>
      <child link="Ring_last_left"/>
      <origin xyz="0 0 0.0384"/>
  </joint>

  <link name="link_11_0_tip_left">
    <visual>
      <geometry>
        <mesh filename="package://bmm3/models/BMM3/BMM3_DAE/sensing_tip.dae" scale="0.001 0.001 0.001"/>
      </geometry>
      <origin rpy="1.5707963 0 1.5707963" xyz="0.0038 0 0.0142"/>
    </visual>
    <collision>
      <material name="white">
        <color rgba="1 1 1 1"/>
      </material>
      <geometry>
        <box size="0.019 0.023 0.025" />
      </geometry>
      <origin xyz="0.0043 0 0.0079" />
    </collision>
    <collision>
      <material name="white"/>
      <geometry>
        <cylinder length="0.019" radius="0.0115"/>
      </geometry>
      <origin rpy="0 -1.5707963 0" xyz="0.0043 0 0.0204" />
    </collision>
  </link>
  
  <joint name="joint_11_0_tip_left" type="fixed">
      <parent link="Ring_last_left"/>
      <child link="link_11_0_tip_left"/>
      <origin xyz="0 0 0.0267"/>
  </joint>

  <link name="Medium_base_left">
    <visual>
      <geometry>
        <mesh filename="package://bmm3/models/BMM3/BMM3_DAE/link_0_0.dae" scale="0.001 0.001 0.001"/>
      </geometry>
      <origin xyz="0 0 0.0164"/>
    </visual>
    <collision>
      <material name="black"/>
      <geometry>
        <box size="0.0196 0.0275 0.0164"/>
      </geometry>
      <origin xyz="0 0 0.0082"/>
    </collision>
  </link>
  
  <joint name="joint_4.0_left" type="revolute">
      <axis xyz="0 0 1"/>
      <limit effort="1" lower="-0.47" upper="0.47" velocity="1"/>
      <parent link="Palm_left"/>
      <child link="Medium_base_left"/>
      <origin xyz="0 0 0.0007"/>
  </joint>

  <link name="Medium_proximal_left">
    <visual>
      <geometry>
        <mesh filename="package://bmm3/models/BMM3/BMM3_DAE/link_1_0.dae" scale="0.001 0.001 0.001"/>
      </geometry>
      <origin rpy="1.5707963 -1.5707963 0"/>
    </visual>
    <collision>
      <material name="black"/>
      <geometry>
        <box size="0.0196 0.0275 0.054"/>
      </geometry>
      <origin xyz="0 0 0.027"/>
    </collision>
  </link>

  <joint name="joint_5.0_left" type="revolute">
      <limit effort="1" lower="-0.196" upper="1.61" velocity="1"/>
      <axis xyz="0 1 0"/>
      <parent link="Medium_base_left"/>
      <child link="Medium_proximal_left"/>
      <origin xyz="0 0 0.0164"/>
  </joint>

  <link name="Medium_distal_left">
    <visual>
      <geometry>
        <mesh filename="package://bmm3/models/BMM3/BMM3_DAE/link_2_0.dae" scale="0.001 0.001 0.001"/>
      </geometry>
      <origin rpy="-1.5707963 -1.5707963 0"/>
    </visual>
    <collision>
      <material name="black"/>
      <geometry>
        <box size="0.0196 0.0275 0.0384"/>
      </geometry>
      <origin xyz="0 0 0.0192"/>
    </collision>
  </link>

  <joint name="joint_6.0_left" type="revolute">
      <axis xyz="0 1 0"/>
      <limit effort="1" lower="-0.174" upper="1.709" velocity="1"/>
      <parent link="Medium_proximal_left"/>
      <child link="Medium_distal_left"/>
      <origin xyz="0 0 0.054"/>
  </joint>

  <link name="Medium_last_left">
    <visual>
      <geometry>
        <mesh filename="package://bmm3/models/BMM3/BMM3_DAE/link_3_0.dae" scale="0.001 0.001 0.001"/>
      </geometry>
      <origin rpy="-1.5707963 -1.5707963 0"/>
    </visual>
    <collision>
      <material name="black"/>
      <geometry>
        <box size="0.0196 0.0275 0.0267"/>
      </geometry>
      <origin xyz="0 0 0.01335"/>
    </collision>
  </link>

  <joint name="joint_7.0_left" type="revolute">
      <axis xyz="0 1 0"/>
      <limit effort="1" lower="-0.227" upper="1.618" velocity="1"/>
      <parent link="Medium_distal_left"/>
      <child link="Medium_last_left"/>
      <origin xyz="0 0 0.0384"/>
  </joint>

  <link name="link_7_0_tip_left">
    <visual>
      <geometry>
        <mesh filename="package://bmm3/models/BMM3/BMM3_DAE/sensing_tip.dae" scale="0.001 0.001 0.001"/>
      </geometry>
      <origin rpy="1.5707963 0 1.5707963" xyz="0.0038 0 0.0142"/>
    </visual>
        <collision>
      <material name="white"/>
      <geometry>
        <box size="0.019 0.023 0.025" />
      </geometry>
      <origin xyz="0.0043 0 0.0079" />
    </collision>
    <collision>
      <material name="white"/>
      <geometry>
        <cylinder length="0.019" radius="0.0115"/>
      </geometry>
      <origin rpy="0 -1.5707963 0" xyz="0.0043 0 0.0204" />
    </collision>
  </link>

  <joint name="joint_7_0_tip_left" type="fixed">
      <parent link="Medium_last_left"/>
      <child link="link_7_0_tip_left"/>
      <origin xyz="0 0 0.0267"/>
  </joint>

  <link name="Index_base_left">
    <visual>
      <geometry>
        <mesh filename="package://bmm3/models/BMM3/BMM3_DAE/link_0_0.dae" scale="0.001 0.001 0.001"/>
      </geometry>
      <origin xyz="0 0 0.0164"/>
    </visual>
    <collision>
      <material name="black"/>
      <geometry>
        <box size="0.0196 0.0275 0.0164"/>
      </geometry>
      <origin xyz="0 0 0.0082"/>
    </collision>
  </link>

  <joint name="joint_0.0_left" type="revolute">
      <axis xyz="0 0 1"/>
      <limit effort="1" lower="-0.47" upper="0.47" velocity="1"/>
      <parent link="Palm_left"/>
      <child link="Index_base_left"/>
      <origin rpy="0.08726646255 0 0" xyz="0 -0.0435 -0.001542"/>
  </joint>

  <link name="Index_proximal_left">
    <visual>
      <geometry>
        <mesh filename="package://bmm3/models/BMM3/BMM3_DAE/link_1_0.dae" scale="0.001 0.001 0.001"/>
      </geometry>
      <origin rpy="1.5707963 -1.5707963 0"/>
    </visual>
    <collision>
      <material name="black"/>
      <geometry>
        <box size="0.0196 0.0275 0.054"/>
      </geometry>
      <origin xyz="0 0 0.027"/>
    </collision>
  </link>

  <joint name="joint_1.0_left" type="revolute">
      <limit effort="1" lower="-0.196" upper="1.61" velocity="1"/>
      <axis xyz="0 1 0"/>
      <parent link="Index_base_left"/>
      <child link="Index_proximal_left"/>
      <origin xyz="0 0 0.0164"/>
  </joint>

  <link name="Index_distal_left">
    <visual>
      <geometry>
        <mesh filename="package://bmm3/models/BMM3/BMM3_DAE/link_2_0.dae" scale="0.001 0.001 0.001"/>
      </geometry>
      <origin rpy="-1.5707963 -1.5707963 0"/>
    </visual>
    <collision>
      <material name="black"/>
      <geometry>
        <box size="0.0196 0.0275 0.0384"/>
      </geometry>
      <origin xyz="0 0 0.0192"/>
    </collision>
  </link>

  <joint name="joint_2.0_left" type="revolute">
      <axis xyz="0 1 0"/>
      <limit effort="1" lower="-0.174" upper="1.709" velocity="1"/>
      <parent link="Index_proximal_left"/>
      <child link="Index_distal_left"/>
      <origin xyz="0 0 0.054"/>
  </joint>

  <link name="Index_last_left">
    <visual>
      <geometry>
        <mesh filename="package://bmm3/models/BMM3/BMM3_DAE/link_3_0.dae" scale="0.001 0.001 0.001"/>
      </geometry>
      <origin rpy="-1.5707963 -1.5707963 0"/>
    </visual>
    <collision>
      <material name="black"/>
      <geometry>
        <box size="0.0196 0.0275 0.0267"/>
      </geometry>
      <origin xyz="0 0 0.01335"/>
    </collision>
  </link>

  <joint name="joint_3.0_left" type="revolute">
      <axis xyz="0 1 0"/>
      <limit effort="1" lower="-0.227" upper="1.618" velocity="1"/>
      <parent link="Index_distal_left"/>
      <child link="Index_last_left"/>
      <origin xyz="0 0 0.0384"/>
  </joint>

  <link name="link_3_0_tip_left">
    <visual>
      <geometry>
        <mesh filename="package://bmm3/models/BMM3/BMM3_DAE/sensing_tip.dae" scale="0.001 0.001 0.001"/>
      </geometry>
      <origin rpy="1.5707963 0 1.5707963" xyz="0.0038 0 0.0142"/>
    </visual>
    <collision>
      <material name="white"/>
      <geometry>
        <box size="0.019 0.023 0.025" />
      </geometry>
      <origin xyz="0.0043 0 0.0079" />
    </collision>
    <collision>
      <material name="white"/>
      <geometry>
        <cylinder length="0.019" radius="0.0115"/>
      </geometry>
      <origin rpy="0 -1.5707963 0" xyz="0.0043 0 0.0204" />
    </collision>
  </link>

  <joint name="joint_3_0_tip_left" type="fixed">
      <parent link="Index_last_left"/>
      <child link="link_3_0_tip_left"/>
      <origin xyz="0 0 0.0267"/>
  </joint>

  <link name="Thumb_base_left">
    <visual>
      <geometry>
        <mesh filename="package://bmm3/models/BMM3/BMM3_DAE/link_12_0_left.dae" scale="0.001 0.001 0.001"/>
      </geometry>
      <origin rpy="-1.570796327 0 -1.570796327" xyz="-0.02775 0 0"/>
    </visual>
    <collision>
      <material name="black"/>
      <geometry>
        <box size="0.0358 0.034 0.0455"/>
      </geometry>
      <origin xyz="-0.0179 0.009 0.0145"/>
    </collision>
  </link>

  <joint name="joint_12.0_left" type="revolute">
      <axis xyz="1 0 0"/>
      <limit effort="1" lower="0.263" upper="1.396" velocity="1"/>
      <parent link="Palm_left"/>
      <child link="Thumb_base_left"/>
    <origin rpy="0 -1.65806278845 1.5707963259" xyz="-0.0182 -0.019333 -0.045987"/>
  </joint>

  <link name="Thumb_proximal_left">
    <visual>
      <geometry>
        <mesh filename="package://bmm3/models/BMM3/BMM3_DAE/link_13_0_left.dae" scale="0.001 0.001 0.001"/>
      </geometry>
      <origin xyz="0 0 0.016000001" rpy="3.141592654 0 3.141592654"/>
    </visual>
    <collision>
      <material name="black"/>
      <geometry>
        <box size="0.0196 0.0275 0.0177"/>
      </geometry>
      <origin xyz="0 0 0.00885"/>
    </collision>
  </link>

  <joint name="joint_13.0_left" type="revolute">
    <axis xyz="0 0 -1"/>
    <limit effort="1" lower="-0.105" upper="1.163" velocity="1"/>
    <parent link="Thumb_base_left"/>
    <child link="Thumb_proximal_left"/>
    <origin xyz="-0.027 0.005 0.0399"/>
  </joint>

  <link name="Thumb_distal_left">
    <visual>
      <geometry>
        <mesh filename="package://bmm3/models/BMM3/BMM3_DAE/link_14_0_left.dae" scale="0.001 0.001 0.001"/>
      </geometry>
      <origin rpy="-1.5707963259 -1.5707963259 0"/>
    </visual>
    <collision>
      <material name="black"/>
      <geometry>
        <box size="0.0196 0.0275 0.0514"/>
      </geometry>
      <origin xyz="0 0 0.0257"/>
    </collision>
  </link>

  <joint name="joint_14.0_left" type="revolute">
      <axis xyz="0 1 0"/>
      <limit effort="1" lower="-0.189" upper="1.644" velocity="1"/>
      <parent link="Thumb_proximal_left"/>
      <child link="Thumb_distal_left"/>
      <origin xyz="0 0 0.0177"/>
  </joint>

  <link name="Thumb_last_left">
    <visual>
      <geometry>
        <mesh filename="package://bmm3/models/BMM3/BMM3_DAE/link_15_0_left.dae" scale="0.001 0.001 0.001"/>
      </geometry>
      <origin rpy="1.5707963259 -1.5707963259 0"/>
    </visual>
    <collision>
      <material name="black"/>
      <geometry>
        <box size="0.0196 0.0275 0.0423"/>
      </geometry>
      <origin xyz="0 0 0.02115"/>
    </collision>
  </link>

  <joint name="joint_15.0_left" type="revolute">
    <axis xyz="0 1 0"/>
    <limit effort="1" lower="-0.162" upper="1.719" velocity="1"/>
    <parent link="Thumb_distal_left"/>
    <child link="Thumb_last_left"/>
    <origin xyz="0 0 0.0514"/>
  </joint>

  <link name="link_15_0_tip_left">
    <visual>
      <geometry>
        <mesh filename="package://bmm3/models/BMM3/BMM3_DAE/sensing_tip.dae" scale="0.001 0.001 0.001"/>
      </geometry>
      <origin rpy="1.5707963 0 1.5707963" xyz="0.0038 0 0.0142"/>
    </visual>
    <collision>
      <material name="white"/>
      <geometry>
        <box size="0.019 0.023 0.025" />
      </geometry>
      <origin xyz="0.0043 0 0.0079" />
    </collision>
    <collision>
      <material name="white"/>
      <geometry>
        <cylinder length="0.019" radius="0.0115"/>
      </geometry>
      <origin rpy="0 -1.5707963 0" xyz="0.0043 0 0.0204" />
    </collision>
  </link>

  <joint name="joint_15_0_tip_left" type="fixed">
      <parent link="Thumb_last_left"/>
      <child link="link_15_0_tip_left"/>
      <origin xyz="0 0 0.0423"/>
  </joint>
  
  <!--- RIGHT ARM -->
  <joint name="connector_right" type="revolute">
    <parent link="base_link"/>
    <child link="Base_right"/>
    <origin rpy="0 2.35619 0" xyz="0.23963 0.0 1.3890"/>
    <axis xyz="-1 0 0"/>
    <limit effort="0" lower="0" upper="0" velocity="0"/>
  </joint>

  <link name="Base_right">
    <visual>
      <geometry>
        <mesh filename="package://bmm3/models/UR5/UR5_DAE/visual/Base.dae"/>
      </geometry>
      <material name="LightGrey">
        <color rgba="0.7 0.7 0.7 1.0"/>
      </material>
    </visual>
    <collision>
      <origin rpy="0 0 0" xyz="0 0 0"/>
      <geometry>
        <mesh filename="package://bmm3/models/UR5/UR5_DAE/collision/Base.stl"/>
      </geometry>
    </collision> 
    <inertial>
      <mass value="4.0"/>
      <origin rpy="0 0 0" xyz="0.0 0.0 0.0"/>
      <inertia ixx="0.00443333156" ixy="0.0" ixz="0.0" iyy="0.00443333156" iyz="0.0" izz="0.0072"/>
    </inertial>
  </link>

  <joint name="ShoulderPanJoint_rigth" type="revolute">
    <parent link="Base_right"/>
    <child link="Shoulder_right"/>
    <origin rpy="0.0 0.0 2.01" xyz="0.0 0.0 0.089159"/>
    <axis xyz="0 0 1"/>
    <limit effort="150.0" lower="-6.2831853" upper="6.2831853" velocity="3.15"/>
    <dynamics damping="0.0" friction="0.0"/>
  </joint>
  
  <link name="Shoulder_right">
    <visual>
      <geometry>
        <mesh filename="package://bmm3/models/UR5/UR5_DAE/visual/Shoulder.dae"/>
      </geometry>
      <material name="LightGrey">
        <color rgba="0.7 0.7 0.7 1.0"/>
      </material>
    </visual>
    <collision>
      <origin rpy="0 0 0"/>
      <geometry>
        <mesh filename="package://bmm3/models/UR5/UR5_DAE/collision/Shoulder.stl"/>
      </geometry>
    </collision>
    <inertial>
      <mass value="3.7"/>
      <origin rpy="0 0 0" xyz="0 0 0"/>
      <inertia ixx="0.010267495893" ixy="0.0" ixz="0.0" iyy="0.010267495893" iyz="0.0" izz="0.00666"/>
    </inertial>
  </link>

  <joint name="ShoulderLiftJoint_right" type="revolute">
    <parent link="Shoulder_right"/>
    <child link="UpperArm_right"/>
    <origin rpy="0.0 -0.4 0.0" xyz="0.0 0.13585 0.0"/>
    <axis xyz="0 1 0"/>
    <limit effort="150.0" lower="-6.2831853" upper="6.2831853" velocity="3.15"/>
    <dynamics damping="0.0" friction="0.0"/>
  </joint>
  
  <link name="UpperArm_right">
    <visual>
      <geometry>
        <mesh filename="package://bmm3/models/UR5/UR5_DAE/visual/UpperArm.dae"/>
      </geometry>
      <material name="LightGrey">
        <color rgba="0.7 0.7 0.7 1.0"/>
      </material>
    </visual>
    <collision>
      <origin rpy="0 0 0"/>
      <geometry>
        <mesh filename="package://bmm3/models/UR5/UR5_DAE/collision/UpperArm.stl"/>
      </geometry>
    </collision>
    <inertial>
      <mass value="8.393"/>
      <origin rpy="0 0 0" xyz="0.0 0.0 0.28"/>
      <inertia ixx="0.22689067591" ixy="0.0" ixz="0.0" iyy="0.22689067591" iyz="0.0" izz="0.0151074"/>
    </inertial>
  </link>

  <joint name="ElbowJoint_right" type="revolute">
    <parent link="UpperArm_right"/>
    <child link="ForeArm_right"/>
    <origin rpy="0.0 1.0 0.0" xyz="0.0 -0.1197 0.425"/>
    <axis xyz="0 1 0"/>
    <limit effort="150.0" lower="-6.2831853" upper="6.2831853" velocity="3.15"/>
    <dynamics damping="0.0" friction="0.0"/>
  </joint>
  
  <link name="ForeArm_right">
    <visual>
      <geometry>
        <mesh filename="package://bmm3/models/UR5/UR5_DAE/visual/Forearm.dae"/>
      </geometry>
      <material name="LightGrey">
        <color rgba="0.7 0.7 0.7 1.0"/>
      </material>
    </visual>
    <collision>
      <origin rpy="0 0 0"/>
      <geometry>
        <mesh filename="package://bmm3/models/UR5/UR5_DAE/collision/ForeArm.stl"/>
      </geometry>
    </collision>
    <inertial>
      <mass value="2.275"/>
      <origin rpy="0 0 0" xyz="0.0 0.0 0.25"/>
      <inertia ixx="0.049443313556" ixy="0.0" ixz="0.0" iyy="0.049443313556" iyz="0.0" izz="0.004095"/>
    </inertial>
  </link>
  
  <joint name="Wrist1Joint_right" type="revolute">
    <parent link="ForeArm_right"/>
    <child link="Wrist1_right"/>
    <origin rpy="0.0 2.0 0.0" xyz="0.0 0.0 0.39225"/>
    <axis xyz="0 1 0"/>
    <limit effort="28.0" lower="-6.2831853" upper="6.2831853" velocity="3.2"/>
    <dynamics damping="0.0" friction="0.0"/>
  </joint>
  
  <link name="Wrist1_right">
    <visual>
      <geometry>
        <mesh filename="package://bmm3/models/UR5/UR5_DAE/visual/Wrist1.dae"/>
      </geometry>
      <material name="LightGrey">
        <color rgba="0.7 0.7 0.7 1.0"/>
      </material>
    </visual>
    <collision>
      <origin rpy="0 0 0"/>
      <geometry>
        <mesh filename="package://bmm3/models/UR5/UR5_DAE/collision/Wrist1.stl"/>
      </geometry>
    </collision>
    <inertial>
      <mass value="1.219"/>
      <origin rpy="0 0 0" xyz="0.0 0.0 0.0"/>
      <inertia ixx="0.111172755531" ixy="0.0" ixz="0.0" iyy="0.111172755531" iyz="0.0" izz="0.21942"/>
    </inertial>
  </link>
  
  <joint name="Wrist2Joint_right" type="revolute">
    <parent link="Wrist1_right"/>
    <child link="Wrist2_right"/>
    <origin rpy="0.0 0.0 0.70" xyz="0.0 0.093 0.0"/>
    <axis xyz="0 0 1"/>
    <limit effort="28.0" lower="-6.2831853" upper="6.2831853" velocity="3.2"/>
    <dynamics damping="0.0" friction="0.0"/>
  </joint>
  
  <link name="Wrist2_right">
    <visual>
      <geometry>
        <mesh filename="package://bmm3/models/UR5/UR5_DAE/visual/Wrist2.dae"/>
      </geometry>
      <material name="LightGrey">
        <color rgba="0.7 0.7 0.7 1.0"/>
      </material>
    </visual>
    <collision>
      <origin rpy="0 0 0"/>
      <geometry>
        <mesh filename="package://bmm3/models/UR5/UR5_DAE/collision/Wrist2.stl"/>
      </geometry>
    </collision>
    <inertial>
      <mass value="1.219"/>
      <origin rpy="0 0 0" xyz="0.0 0.0 0.0"/>
      <inertia ixx="0.111172755531" ixy="0.0" ixz="0.0" iyy="0.111172755531" iyz="0.0" izz="0.21942"/>
    </inertial>
  </link>
  
  <joint name="Wrist3Joint_right" type="revolute">
    <parent link="Wrist2_right"/>
    <child link="Wrist3_right"/>
    <origin rpy="0.0 0.0 0.0" xyz="0.0 0.0 0.09465"/>
    <axis xyz="0 1 0"/>
    <limit effort="28.0" lower="-6.2831853" upper="6.2831853" velocity="3.2"/>
    <dynamics damping="0.0" friction="0.0"/>
  </joint>
  
  <link name="Wrist3_right">
    <visual>
      <geometry>
        <mesh filename="package://bmm3/models/UR5/UR5_DAE/visual/Wrist3.dae"/>
      </geometry>
      <material name="LightGrey">
        <color rgba="0.7 0.7 0.7 1.0"/>
      </material>
    </visual>
    <collision>
      <origin rpy="0 0 0"/>
      <geometry>
        <mesh filename="package://bmm3/models/UR5/UR5_DAE/collision/Wrist3.stl"/>
      </geometry>
    </collision>
    <inertial>
      <mass value="0.1879"/>
      <origin rpy="0 0 0" xyz="0.0 0.0 0.0"/>
      <inertia ixx="0.0171364731454" ixy="0.0" ixz="0.0" iyy="0.0171364731454" iyz="0.0" izz="0.033822"/>
    </inertial>
  </link>

  <!-- RIGHT HAND -->
  <joint name="SupportJoint_right" type="fixed">
    <parent link="Wrist3_right"/>
    <child link="Support_right"/>
    <origin rpy="-1.570796325 0 0" xyz="0 0.1089 0"/>
  </joint>

  <link name="Support_right">
    <visual>
      <geometry>
        <mesh filename="package://bmm3/models/BMM3/BMM3_DAE/AH_support.dae" scale="0.001 0.001 0.001"/>
      </geometry>
    </visual>
    <collision>
      <material name="grey"/>
      <origin xyz="0 0 -0.0055" rpy="0 0 1.570796327"/>
      <geometry>
         <cylinder radius="0.0355" length="0.043"/>
      </geometry>
    </collision>
  </link>

  <joint name="PalmJoint_right" type="fixed">
    <parent link="Support_right"/>
    <child link="Palm_right"/>
    <origin rpy="0 0 1.570796327" xyz="0 0.009 0.111"/>
  </joint>

  <link name="Palm_right">
    <visual>
      <geometry>
	<mesh filename="package://bmm3/models/BMM3/BMM3_DAE/base_link_right.dae" scale="0.001 0.001 0.001"/>
      </geometry>
    </visual>
    <collision>
      <material name="black"/>
	<origin xyz="-0.009300 0 -0.0475"/>
	<geometry>
	  <box size="0.0408 0.1130 0.095"/>
	</geometry>
    </collision>
  </link>

  <joint name="joint_8.0_right" type="revolute">
      <axis xyz="0 0 1"/>
      <limit effort="1" lower="-0.47" upper="0.47" velocity="1"/>
      <parent link="Palm_right"/>
      <child link="Ring_base_right"/>
      <origin rpy="-0.08726646255 0 0" xyz="0 0.0435 -0.001542"/>
  </joint>

  <link name="Ring_base_right">
    <visual>
      <geometry>
        <mesh filename="package://bmm3/models/BMM3/BMM3_DAE/link_0_0.dae" scale="0.001 0.001 0.001"/>
      </geometry>
      <origin xyz="0 0 0.0164"/>
    </visual>
    <collision>
      <material name="black"/>
      <geometry>
        <box size="0.0196 0.0275 0.0164"/>
      </geometry>
      <origin xyz="0 0 0.0082"/>
    </collision>
  </link>

  <link name="Ring_proximal_right">
    <visual>
      <geometry>
        <mesh filename="package://bmm3/models/BMM3/BMM3_DAE/link_1_0.dae" scale="0.001 0.001 0.001"/>
      </geometry>
      <origin rpy="1.5707963 -1.5707963 0"/>
    </visual>
    <collision>
      <material name="black"/>
      <geometry>
        <box size="0.0196 0.0275 0.054"/>
      </geometry>
      <origin xyz="0 0 0.027"/>
    </collision>
  </link>

  <joint name="joint_9.0_right" type="revolute">
      <limit effort="1" lower="-0.196" upper="1.61" velocity="1"/>
      <axis xyz="0 1 0"/>
      <parent link="Ring_base_right"/>
      <child link="Ring_proximal_right"/>
      <origin xyz="0 0 0.0164"/>
  </joint>

  <link name="Ring_distal_right">
    <visual>
      <geometry>
        <mesh filename="package://bmm3/models/BMM3/BMM3_DAE/link_2_0.dae" scale="0.001 0.001 0.001"/>
      </geometry>
      <origin rpy="-1.5707963 -1.5707963 0"/>
    </visual>
    <collision>
      <material name="black"/>
      <geometry>
        <box size="0.0196 0.0275 0.0384"/>
      </geometry>
      <origin xyz="0 0 0.0192"/>
    </collision>
  </link>
  
  <joint name="joint_10.0_right" type="revolute">
      <axis xyz="0 1 0"/>
      <limit effort="1" lower="-0.174" upper="1.709" velocity="1"/>
      <parent link="Ring_proximal_right"/>
      <child link="Ring_distal_right"/>
      <origin xyz="0 0 0.054"/>
  </joint>

  <link name="Ring_last_right">
    <visual>
      <geometry>
        <mesh filename="package://bmm3/models/BMM3/BMM3_DAE/link_3_0.dae" scale="0.001 0.001 0.001"/>
      </geometry>
      <origin rpy="-1.5707963 -1.5707963 0"/>
    </visual>
    <collision>
      <material name="black"/>
      <geometry>
        <box size="0.0196 0.0275 0.0267"/>
      </geometry>
      <origin xyz="0 0 0.01335"/>
    </collision>
  </link>
  
  <joint name="joint_11.0_right" type="revolute">
      <axis xyz="0 1 0"/>
      <limit effort="1" lower="-0.227" upper="1.618" velocity="1"/>
      <parent link="Ring_distal_right"/>
      <child link="Ring_last_right"/>
      <origin xyz="0 0 0.0384"/>
  </joint>

  <link name="link_11_0_tip_right">
    <visual>
      <geometry>
        <mesh filename="package://bmm3/models/BMM3/BMM3_DAE/sensing_tip.dae" scale="0.001 0.001 0.001"/>
      </geometry>
      <origin rpy="1.5707963 0 1.5707963" xyz="0.0038 0 0.0142"/>
    </visual>
    <collision>
      <material name="white">
        <color rgba="1 1 1 1"/>
      </material>
      <geometry>
        <box size="0.019 0.023 0.025" />
      </geometry>
      <origin xyz="0.0043 0 0.0079" />
    </collision>
    <collision>
      <material name="white"/>
      <geometry>
        <cylinder length="0.019" radius="0.0115"/>
      </geometry>
      <origin rpy="0 -1.5707963 0" xyz="0.0043 0 0.0204" />
    </collision>
  </link>
  
  <joint name="joint_11_0_tip_right" type="fixed">
      <parent link="Ring_last_right"/>
      <child link="link_11_0_tip_right"/>
      <origin xyz="0 0 0.0267"/>
  </joint>

  <link name="Medium_base_right">
    <visual>
      <geometry>
        <mesh filename="package://bmm3/models/BMM3/BMM3_DAE/link_0_0.dae" scale="0.001 0.001 0.001"/>
      </geometry>
      <origin xyz="0 0 0.0164"/>
    </visual>
    <collision>
      <material name="black"/>
      <geometry>
        <box size="0.0196 0.0275 0.0164"/>
      </geometry>
      <origin xyz="0 0 0.0082"/>
    </collision>
  </link>
  
  <joint name="joint_4.0_right" type="revolute">
      <axis xyz="0 0 1"/>
      <limit effort="1" lower="-0.47" upper="0.47" velocity="1"/>
      <parent link="Palm_right"/>
      <child link="Medium_base_right"/>
      <origin xyz="0 0 0.0007"/>
  </joint>

  <link name="Medium_proximal_right">
    <visual>
      <geometry>
        <mesh filename="package://bmm3/models/BMM3/BMM3_DAE/link_1_0.dae" scale="0.001 0.001 0.001"/>
      </geometry>
      <origin rpy="1.5707963 -1.5707963 0"/>
    </visual>
    <collision>
      <material name="black"/>
      <geometry>
        <box size="0.0196 0.0275 0.054"/>
      </geometry>
      <origin xyz="0 0 0.027"/>
    </collision>
  </link>

  <joint name="joint_5.0_right" type="revolute">
      <limit effort="1" lower="-0.196" upper="1.61" velocity="1"/>
      <axis xyz="0 1 0"/>
      <parent link="Medium_base_right"/>
      <child link="Medium_proximal_right"/>
      <origin xyz="0 0 0.0164"/>
  </joint>

  <link name="Medium_distal_right">
    <visual>
      <geometry>
        <mesh filename="package://bmm3/models/BMM3/BMM3_DAE/link_2_0.dae" scale="0.001 0.001 0.001"/>
      </geometry>
      <origin rpy="-1.5707963 -1.5707963 0"/>
    </visual>
    <collision>
      <material name="black"/>
      <geometry>
        <box size="0.0196 0.0275 0.0384"/>
      </geometry>
      <origin xyz="0 0 0.0192"/>
    </collision>
  </link>

  <joint name="joint_6.0_right" type="revolute">
      <axis xyz="0 1 0"/>
      <limit effort="1" lower="-0.174" upper="1.709" velocity="1"/>
      <parent link="Medium_proximal_right"/>
      <child link="Medium_distal_right"/>
      <origin xyz="0 0 0.054"/>
  </joint>

  <link name="Medium_last_right">
    <visual>
      <geometry>
        <mesh filename="package://bmm3/models/BMM3/BMM3_DAE/link_3_0.dae" scale="0.001 0.001 0.001"/>
      </geometry>
      <origin rpy="-1.5707963 -1.5707963 0"/>
    </visual>
    <collision>
      <material name="black"/>
      <geometry>
        <box size="0.0196 0.0275 0.0267"/>
      </geometry>
      <origin xyz="0 0 0.01335"/>
    </collision>
  </link>

  <joint name="joint_7.0_right" type="revolute">
      <axis xyz="0 1 0"/>
      <limit effort="1" lower="-0.227" upper="1.618" velocity="1"/>
      <parent link="Medium_distal_right"/>
      <child link="Medium_last_right"/>
      <origin xyz="0 0 0.0384"/>
  </joint>

  <link name="link_7_0_tip_right">
    <visual>
      <geometry>
        <mesh filename="package://bmm3/models/BMM3/BMM3_DAE/sensing_tip.dae" scale="0.001 0.001 0.001"/>
      </geometry>
      <origin rpy="1.5707963 0 1.5707963" xyz="0.0038 0 0.0142"/>
    </visual>
        <collision>
      <material name="white"/>
      <geometry>
        <box size="0.019 0.023 0.025" />
      </geometry>
      <origin xyz="0.0043 0 0.0079" />
    </collision>
    <collision>
      <material name="white"/>
      <geometry>
        <cylinder length="0.019" radius="0.0115"/>
      </geometry>
      <origin rpy="0 -1.5707963 0" xyz="0.0043 0 0.0204" />
    </collision>
  </link>

  <joint name="joint_7_0_tip_right" type="fixed">
      <parent link="Medium_last_right"/>
      <child link="link_7_0_tip_right"/>
      <origin xyz="0 0 0.0267"/>
  </joint>

  <link name="Index_base_right">
    <visual>
      <geometry>
        <mesh filename="package://bmm3/models/BMM3/BMM3_DAE/link_0_0.dae" scale="0.001 0.001 0.001"/>
      </geometry>
      <origin xyz="0 0 0.0164"/>
    </visual>
    <collision>
      <material name="black"/>
      <geometry>
        <box size="0.0196 0.0275 0.0164"/>
      </geometry>
      <origin xyz="0 0 0.0082"/>
    </collision>
  </link>

  <joint name="joint_0.0_right" type="revolute">
      <axis xyz="0 0 1"/>
      <limit effort="1" lower="-0.47" upper="0.47" velocity="1"/>
      <parent link="Palm_right"/>
      <child link="Index_base_right"/>
      <origin rpy="0.08726646255 0 0" xyz="0 -0.0435 -0.001542"/>
  </joint>

  <link name="Index_proximal_right">
    <visual>
      <geometry>
        <mesh filename="package://bmm3/models/BMM3/BMM3_DAE/link_1_0.dae" scale="0.001 0.001 0.001"/>
      </geometry>
      <origin rpy="1.5707963 -1.5707963 0"/>
    </visual>
    <collision>
      <material name="black"/>
      <geometry>
        <box size="0.0196 0.0275 0.054"/>
      </geometry>
      <origin xyz="0 0 0.027"/>
    </collision>
  </link>

  <joint name="joint_1.0_right" type="revolute">
      <limit effort="1" lower="-0.196" upper="1.61" velocity="1"/>
      <axis xyz="0 1 0"/>
      <parent link="Index_base_right"/>
      <child link="Index_proximal_right"/>
      <origin xyz="0 0 0.0164"/>
  </joint>

  <link name="Index_distal_right">
    <visual>
      <geometry>
        <mesh filename="package://bmm3/models/BMM3/BMM3_DAE/link_2_0.dae" scale="0.001 0.001 0.001"/>
      </geometry>
      <origin rpy="-1.5707963 -1.5707963 0"/>
    </visual>
    <collision>
      <material name="black"/>
      <geometry>
        <box size="0.0196 0.0275 0.0384"/>
      </geometry>
      <origin xyz="0 0 0.0192"/>
    </collision>
  </link>

  <joint name="joint_2.0_right" type="revolute">
      <axis xyz="0 1 0"/>
      <limit effort="1" lower="-0.174" upper="1.709" velocity="1"/>
      <parent link="Index_proximal_right"/>
      <child link="Index_distal_right"/>
      <origin xyz="0 0 0.054"/>
  </joint>

  <link name="Index_last_right">
    <visual>
      <geometry>
        <mesh filename="package://bmm3/models/BMM3/BMM3_DAE/link_3_0.dae" scale="0.001 0.001 0.001"/>
      </geometry>
      <origin rpy="-1.5707963 -1.5707963 0"/>
    </visual>
    <collision>
      <material name="black"/>
      <geometry>
        <box size="0.0196 0.0275 0.0267"/>
      </geometry>
      <origin xyz="0 0 0.01335"/>
    </collision>
  </link>

  <joint name="joint_3.0_right" type="revolute">
      <axis xyz="0 1 0"/>
      <limit effort="1" lower="-0.227" upper="1.618" velocity="1"/>
      <parent link="Index_distal_right"/>
      <child link="Index_last_right"/>
      <origin xyz="0 0 0.0384"/>
  </joint>

  <link name="link_3_0_tip_right">
    <visual>
      <geometry>
        <mesh filename="package://bmm3/models/BMM3/BMM3_DAE/sensing_tip.dae" scale="0.001 0.001 0.001"/>
      </geometry>
      <origin rpy="1.5707963 0 1.5707963" xyz="0.0038 0 0.0142"/>
    </visual>
    <collision>
      <material name="white"/>
      <geometry>
        <box size="0.019 0.023 0.025" />
      </geometry>
      <origin xyz="0.0043 0 0.0079" />
    </collision>
    <collision>
      <material name="white"/>
      <geometry>
        <cylinder length="0.019" radius="0.0115"/>
      </geometry>
      <origin rpy="0 -1.5707963 0" xyz="0.0043 0 0.0204" />
    </collision>
  </link>

  <joint name="joint_3_0_tip_right" type="fixed">
      <parent link="Index_last_right"/>
      <child link="link_3_0_tip_right"/>
      <origin xyz="0 0 0.0267"/>
  </joint>

  <link name="Thumb_base_right">
    <visual>
      <geometry>
        <mesh filename="package://bmm3/models/BMM3/BMM3_DAE/link_12_0_right.dae" scale="0.001 0.001 0.001"/>
      </geometry>
      <origin rpy="1.570796327 0 -1.570796327" xyz="-0.02775 0 0"/>
    </visual>
    <collision>
      <material name="black"/>
      <geometry>
        <box size="0.0358 0.034 0.0455"/>
      </geometry>
      <origin xyz="-0.0179 0.009 0.0145"/>
    </collision>
  </link>

  <joint name="joint_12.0_right" type="revolute">
      <axis xyz="-1 0 0"/>
      <limit effort="1" lower="0.263" upper="1.396" velocity="1"/>
      <parent link="Palm_right"/>
      <child link="Thumb_base_right"/>
    <origin rpy="0 -1.65806278845 -1.5707963259" xyz="-0.0182 0.019333 -0.045987"/>
  </joint>

  <link name="Thumb_proximal_right">
    <visual>
      <geometry>
        <mesh filename="package://bmm3/models/BMM3/BMM3_DAE/link_13_0_right.dae" scale="0.001 0.001 0.001"/>
      </geometry>
      <origin xyz="0 0 0.016000001"/>
    </visual>
    <collision>
      <material name="black"/>
      <geometry>
        <box size="0.0196 0.0275 0.0177"/>
      </geometry>
      <origin xyz="0 0 0.00885"/>
    </collision>
  </link>

  <joint name="joint_13.0_right" type="revolute">
    <axis xyz="0 0 1"/>
    <limit effort="1" lower="-0.105" upper="1.163" velocity="1"/>
    <parent link="Thumb_base_right"/>
    <child link="Thumb_proximal_right"/>
    <origin xyz="-0.027 0.005 0.0399"/>
  </joint>

  <link name="Thumb_distal_right">
    <visual>
      <geometry>
        <mesh filename="package://bmm3/models/BMM3/BMM3_DAE/link_14_0_right.dae" scale="0.001 0.001 0.001"/>
      </geometry>
      <origin rpy="-1.5707963259 1.5707963259 0"/>
    </visual>
    <collision>
      <material name="black"/>
      <geometry>
        <box size="0.0196 0.0275 0.0514"/>
      </geometry>
      <origin xyz="0 0 0.0257"/>
    </collision>
  </link>

  <joint name="joint_14.0_right" type="revolute">
      <axis xyz="0 1 0"/>
      <limit effort="1" lower="-0.189" upper="1.644" velocity="1"/>
      <parent link="Thumb_proximal_right"/>
      <child link="Thumb_distal_right"/>
      <origin xyz="0 0 0.0177"/>
  </joint>

  <link name="Thumb_last_right">
    <visual>
      <geometry>
        <mesh filename="package://bmm3/models/BMM3/BMM3_DAE/link_15_0_right.dae" scale="0.001 0.001 0.001"/>
      </geometry>
      <origin rpy="1.5707963259 1.5707963259 0"/>
    </visual>
    <collision>
      <material name="black"/>
      <geometry>
        <box size="0.0196 0.0275 0.0423"/>
      </geometry>
      <origin xyz="0 0 0.02115"/>
    </collision>
  </link>

  <joint name="joint_15.0_right" type="revolute">
    <axis xyz="0 1 0"/>
    <limit effort="1" lower="-0.162" upper="1.719" velocity="1"/>
    <parent link="Thumb_distal_right"/>
    <child link="Thumb_last_right"/>
    <origin xyz="0 0 0.0514"/>
  </joint>

  <link name="link_15_0_tip_right">
    <visual>
      <geometry>
        <mesh filename="package://bmm3/models/BMM3/BMM3_DAE/sensing_tip.dae" scale="0.001 0.001 0.001"/>
      </geometry>
      <origin rpy="1.5707963 0 1.5707963" xyz="0.0038 0 0.0142"/>
    </visual>
    <collision>
      <material name="white"/>
      <geometry>
        <box size="0.019 0.023 0.025" />
      </geometry>
      <origin xyz="0.0043 0 0.0079" />
    </collision>
    <collision>
      <material name="white"/>
      <geometry>
        <cylinder length="0.019" radius="0.0115"/>
      </geometry>
      <origin rpy="0 -1.5707963 0" xyz="0.0043 0 0.0204" />
    </collision>
  </link>

  <joint name="joint_15_0_tip_right" type="fixed">
      <parent link="Thumb_last_right"/>
      <child link="link_15_0_tip_right"/>
      <origin xyz="0 0 0.0423"/>
  </joint>

</robot>